import XCTest

// Helper function from https://stackoverflow.com/questions/58633811/how-to-assert-an-error-is-thrown-async-when-testing
func assertThrowsAsyncError<T>(
    _ expression: @autoclosure () async throws -> T,
    _ message: @autoclosure () -> String = "",
    file: StaticString = #filePath,
    line: UInt = #line,
    _ errorHandler: (_ error: Error) -> Void = { _ in }) async {
    do {
        _ = try await expression()
        // expected error to be thrown, but it was not
        let customMessage = message()
        if customMessage.isEmpty {
            XCTFail("Asynchronous call did not throw an error.", file: file, line: line)
        } else {
            XCTFail(customMessage, file: file, line: line)
        }
    } catch {
        errorHandler(error)
    }
}

